Workbook

Sheet README
A1: Item | B1: Description
A2: Purpose | B2: Machine-readable correspondence tables between the TBIM (Topologic JSON), IFC, Honeybee (HB) and EnergyPlus (E+) used by the BIM-to-BEM workflow, plus the values actually present in each model. They extend Tables 7, 8 and 9 of the Appendix of the paper.
A3: Workflow analysed | B3: scripts/01_bim_to_bem.py, src/digitmanpy/Operation.py (classes Utils, HB, Eppy, TBIM). The tuning (scripts/02_bem_calibration.py) edits the IDF directly.
A4: Value sources | B4: TBIM: data/<building>/<building>_tbim_topologic.json (Cell / Face / Aperture dictionaries). IFC: *_tbim_ifc_design_transfer_view.ifc (spaces, element types, glazing psets) and *_tbim_ifc_reference_view.ifc (material properties). E+: models/*_bem_baseline.idf (baseline = direct output of the workflow) and models/*_bem_calibrated.idf (after manual calibration). Schedules: data/schedules/*.json.
A5: Author decisions (2026-10-16) | B5: Report the CALIBRATED model and replace Appendix values with model values, EXCEPT ventilation/infiltration (EN 16798 values already in the paper) and temperature setpoints (values cited in the paper: 20 / 15 °C heating, 26 °C cooling), both kept in Ref_Assumptions. Table 8 = every outer-envelope construction; Table 7 indexed by EnergyPlus zone; Table 9 reports the 23 B09 curtain-wall panels with their BIM glazing (VT 0.58).
A6: Sheet: Ref_Assumptions | B6: Reference ventilation/infiltration inputs (yellow, editable) used by T7, plus AHU-capacity checks.
A7: Sheet: T7_Zones / T7_Grouped | B7: Proposed Appendix Table 7: one row per E+ zone (calibrated IDF) and a condensed version grouping identical zones (for the manuscript).
A8: Sheet: T8_Envelope | B8: Proposed Appendix Table 8: every outer-envelope construction with layers and computed U (live formulas).
A9: Sheet: T9_Glazing | B9: Proposed Appendix Table 9: glazing constructions with U/SHGC/VT, BIM glass/frame data and areas.
A10: Sheet: Map_Spaces | B10: Space / zone properties (Appendix Table 7). One row per property.
A11: Sheet: Map_Envelope | B11: Opaque constructions, materials, surfaces and boundary conditions (Appendix Table 8).
A12: Sheet: Map_Apertures | B12: Windows, doors, curtain walls, blinds (Appendix Table 9).
... A25: Generated | B25: 2026-10-16 from the files listed above (no values typed by hand except where a row says 'notebook constant' or 'HB default').

Sheet Ref_Assumptions
A1: Key | B1: Parameter | C1: Value | D1: Unit | E1: Source / note
A2: OA_per_person | B2: Outdoor air per person (occupied, ventilated zones) | C2: 10 | D2: L/s·person | E2: Value reported in the paper (Methods, EN 16798-1 Cat. II); author decision 2026-10-16. Repository IDF: 7 L/s·p.
A3: OA_per_area | B3: Outdoor air per floor area (building emissions) | C3: 0.6 | D3: L/s·m² | E3: Value reported in the paper (Methods); author decision 2026-10-16. Repository IDF: TBIM air-change rate written as L/s·m².
A4: OA_unoccupied | B4: Outdoor air when unoccupied / night | C4: 0 | D4: L/s | E4: Methods: night-time/unoccupied lower limit = 0 (infiltration only).
A5: Infiltration_ACH | B5: Infiltration (envelope) | C5: 0.3 | D5: h⁻¹ | E5: Methods: 0.3 ACH. Repository IDF: 0.0001 m³/s per m² exterior surface ('TightBuilding').
A6: AHU_cap_B09 | B6: AHU maximum airflow – Building 09 | C6: 7200 | D6: m³/h | E6: Methods.
A7: AHU_cap_B10 | B7: AHU maximum airflow – Building 10 | C7: 11000 | D7: m³/h | E7: Methods.
A8: Heating_SP_occupied | B8: Heating setpoint – occupied | C8: 20 | D8: °C | E8: Paper Table 7 (Space Temperature Winter Max, occupied heating setpoint); author decision 2026-10-16. Calibrated IDF: B09 18 °C, B10 22 °C.
A9: Heating_SP_setback | B9: Heating setpoint – night / weekend setback | C9: 15 | D9: °C | E9: Paper Table 7 (Space Temperature Winter Min). Calibrated IDF: B09 15 °C, B10 18 °C.
A10: Cooling_SP_occupied | B10: Cooling setpoint – occupied | C10: 26 | D10: °C | E10: Paper Table 7 (Space Temperature Summer Max). Calibrated IDF: B09 20 °C, B10 22 °C.
A12: Check | B12: Sum of design outdoor airflow – B09 | C12: =SUMIFS(T7_Zones!$U$2:$U$86,T7_Zones!$A$2:$A$86,"B09") | D12: m³/h | E12: Compare with AHU_cap_B09 (C6).
A13: Check | B13: Sum of design outdoor airflow – B10 | C13: =SUMIFS(T7_Zones!$U$2:$U$86,T7_Zones!$A$2:$A$86,"B10") | D13: m³/h | E13: Compare with AHU_cap_B10 (C7).
A14: Check | B14: Design airflow / AHU capacity – B09 | C14: =C12/C6 | D14: – | E14: > 1 means the AHU cap limits the outdoor air.
A15: Check | B15: Design airflow / AHU capacity – B10 | C15: =C13/C7 | D15: – | E15: > 1 means the AHU cap limits the outdoor air.

Sheet T7_Zones
A1: Building | B1: E+ zone | C1: Zone use (inferred from E+ loads) | D1: Floor area (m²) | E1: Occupancy density (person/m²) | F1: Design occupants (persons) | G1: Occupancy schedule | H1: Lighting power density (W/m²) | I1: Lighting schedule | J1: Equipment power density (W/m²) | K1: Equipment schedule | L1: Heating setpoint occupied (°C) – paper | M1: Heating setback (°C) – paper | N1: Cooling setpoint occupied (°C) – paper | O1: RH max – dehumidification (%) | P1: RH min – humidification (%) | Q1: HVAC availability (heating / cooling / ventilation) | R1: Mechanically ventilated | S1: OA per person (L/s·p) – reported | T1: OA per area (L/s·m²) – reported | U1: Design outdoor airflow (m³/h) | V1: Infiltration (h⁻¹) – reported | W1: OA per person in repository IDF (L/s·p) | X1: TBIM air-change rate written to IDF (h⁻¹) | Y1: Heating SP in calibrated IDF (occupied / otherwise, °C) | Z1: Cooling SP in calibrated IDF (°C)
A2: B09 | B2: debugZone0 | C2: Unconditioned (stairs, shafts, storage, parking) – cell not clustered | D2: 83.06 | E2: 0 | F2: =D2*E2 | G2: OccSch_Unoccupied | H2: 6 | I2: LghSch_Costant | J2: 2 | K2: EqpSch_Costant | L2: =IF(R2="Yes",Ref_Assumptions!$C$8,"–") | M2: =IF(R2="Yes",Ref_Assumptions!$C$9,"–") | N2: =IF(R2="Yes",Ref_Assumptions!$C$10,"–") | O2: 70 | P2: 40 | Q2: Off (AlwaysOff) | R2: No | S2: =IF(R2="Yes",Ref_Assumptions!$C$2,Ref_Assumptions!$C$4) | T2: =IF(R2="Yes",Ref_Assumptions!$C$3,Ref_Assumptions!$C$4) | U2: =(F2*S2+D2*T2)*3.6 | V2: =Ref_Assumptions!$C$5 | W2: 0 | X2: 0 | Y2: 18 / 15 | Z2: 20
A3: B09 | B3: debugZone1 | C3: Unconditioned (stairs, shafts, storage, parking) – cell not clustered | D3: 83.06 | E3: 0 | F3: =D3*E3 | G3: OccSch_Unoccupied | H3: 6 | I3: LghSch_Costant | J3: 2 | K3: EqpSch_Costant | L3: =IF(R3="Yes",Ref_Assumptions!$C$8,"–") | M3: =IF(R3="Yes",Ref_Assumptions!$C$9,"–") | N3: =IF(R3="Yes",Ref_Assumptions!$C$10,"–") | O3: 70 | P3: 40 | Q3: Off (AlwaysOff) | R3: No | S3: =IF(R3="Yes",Ref_Assumptions!$C$2,Ref_Assumptions!$C$4) | T3: =IF(R3="Yes",Ref_Assumptions!$C$3,Ref_Assumptions!$C$4) | U3: =(F3*S3+D3*T3)*3.6 | V3: =Ref_Assumptions!$C$5 | W3: 0 | X3: 0 | Y3: 18 / 15 | Z3: 20
A4: B09 | B4: debugZone10 | C4: Research laboratory – cell not clustered | D4: 37.39 | E4: 0.3 | F4: =D4*E4 | G4: OccSch_Unoccupied | H4: 6 | I4: LghSch_Costant | J4: 2 | K4: EqpSch_Costant | L4: =IF(R4="Yes",Ref_Assumptions!$C$8,"–") | M4: =IF(R4="Yes",Ref_Assumptions!$C$9,"–") | N4: =IF(R4="Yes",Ref_Assumptions!$C$10,"–") | O4: 70 | P4: 40 | Q4: Always on (calibrated AHU schedules = 1) | R4: Yes | S4: =IF(R4="Yes",Ref_Assumptions!$C$2,Ref_Assumptions!$C$4) | T4: =IF(R4="Yes",Ref_Assumptions!$C$3,Ref_Assumptions!$C$4) | U4: =(F4*S4+D4*T4)*3.6 | V4: =Ref_Assumptions!$C$5 | W4: 7 | X4: 1.76911 | Y4: 18 / 15 | Z4: 20
A5: B09 | B5: debugZone11 | C5: Conditioned service / circulation – cell not clustered | D5: 6.46 | E5: 0 | F5: =D5*E5 | G5: OccSch_Unoccupied | H5: 6 | I5: LghSch_Costant | J5: 2 | K5: EqpSch_Costant | L5: =IF(R5="Yes",Ref_Assumptions!$C$8,"–") | M5: =IF(R5="Yes",Ref_Assumptions!$C$9,"–") | N5: =IF(R5="Yes",Ref_Assumptions!$C$10,"–") | O5: 70 | P5: 40 | Q5: Always on (calibrated AHU schedules = 1) | R5: Yes | S5: =IF(R5="Yes",Ref_Assumptions!$C$2,Ref_Assumptions!$C$4) | T5: =IF(R5="Yes",Ref_Assumptions!$C$3,Ref_Assumptions!$C$4) | U5: =(F5*S5+D5*T5)*3.6 | V5: =Ref_Assumptions!$C$5 | W5: 0 | X5: 0 | Y5: 18 / 15 | Z5: 20
A6: B09 | B6: debugZone2 | C6: Unconditioned (stairs, shafts, storage, parking) – cell not clustered | D6: 73.89 | E6: 0 | F6: =D6*E6 | G6: OccSch_Unoccupied | H6: 6 | I6: LghSch_Costant | J6: 2 | K6: EqpSch_Costant | L6: =IF(R6="Yes",Ref_Assumptions!$C$8,"–") | M6: =IF(R6="Yes",Ref_Assumptions!$C$9,"–") | N6: =IF(R6="Yes",Ref_Assumptions!$C$10,"–") | O6: 70 | P6: 40 | Q6: Off (AlwaysOff) | R6: No | S6: =IF(R6="Yes",Ref_Assumptions!$C$2,Ref_Assumptions!$C$4) | T6: =IF(R6="Yes",Ref_Assumptions!$C$3,Ref_Assumptions!$C$4) | U6: =(F6*S6+D6*T6)*3.6 | V6: =Ref_Assumptions!$C$5 | W6: 0 | X6: 0 | Y6: 18 / 15 | Z6: 20
A7: B09 | B7: debugZone3 | C7: Unconditioned (stairs, shafts, storage, parking) – cell not clustered | D7: 31.04 | E7: 0 | F7: =D7*E7 | G7: OccSch_Unoccupied | H7: 6 | I7: LghSch_Costant | J7: 2 | K7: EqpSch_Costant | L7: =IF(R7="Yes",Ref_Assumptions!$C$8,"–") | M7: =IF(R7="Yes",Ref_Assumptions!$C$9,"–") | N7: =IF(R7="Yes",Ref_Assumptions!$C$10,"–") | O7: 70 | P7: 40 | Q7: Off (AlwaysOff) | R7: No | S7: =IF(R7="Yes",Ref_Assumptions!$C$2,Ref_Assumptions!$C$4) | T7: =IF(R7="Yes",Ref_Assumptions!$C$3,Ref_Assumptions!$C$4) | U7: =(F7*S7+D7*T7)*3.6 | V7: =Ref_Assumptions!$C$5 | W7: 0 | X7: 0 | Y7: 18 / 15 | Z7: 20
A8: B09 | B8: debugZone4 | C8: Research laboratory – cell not clustered | D8: 81.83 | E8: 0.3 | F8: =D8*E8 | G8: OccSch_Unoccupied | H8: 6 | I8: LghSch_Costant | J8: 2 | K8: EqpSch_Costant | L8: =IF(R8="Yes",Ref_Assumptions!$C$8,"–") | M8: =IF(R8="Yes",Ref_Assumptions!$C$9,"–") | N8: =IF(R8="Yes",Ref_Assumptions!$C$10,"–") | O8: 70 | P8: 40 | Q8: Always on (calibrated AHU schedules = 1) | R8: Yes | S8: =IF(R8="Yes",Ref_Assumptions!$C$2,Ref_Assumptions!$C$4) | T8: =IF(R8="Yes",Ref_Assumptions!$C$3,Ref_Assumptions!$C$4) | U8: =(F8*S8+D8*T8)*3.6 | V8: =Ref_Assumptions!$C$5 | W8: 7 | X8: 1.66298 | Y8: 18 / 15 | Z8: 20
A9: B09 | B9: debugZone5 | C9: Research laboratory – cell not clustered | D9: 82.54 | E9: 0.3 | F9: =D9*E9 | G9: OccSch_Unoccupied | H9: 6 | I9: LghSch_Costant | J9: 2 | K9: EqpSch_Costant | L9: =IF(R9="Yes",Ref_Assumptions!$C$8,"–") | M9: =IF(R9="Yes",Ref_Assumptions!$C$9,"–") | N9: =IF(R9="Yes",Ref_Assumptions!$C$10,"–") | O9: 70 | P9: 40 | Q9: Always on (calibrated AHU schedules = 1) | R9: Yes | S9: =IF(R9="Yes",Ref_Assumptions!$C$2,Ref_Assumptions!$C$4) | T9: =IF(R9="Yes",Ref_Assumptions!$C$3,Ref_Assumptions!$C$4) | U9: =(F9*S9+D9*T9)*3.6 | V9: =Ref_Assumptions!$C$5 | W9: 7 | X9: 1.48361 | Y9: 18 / 15 | Z9: 20
A10: B09 | B10: debugZone6 | C10: Research laboratory – cell not clustered | D10: 61 | E10: 0.3 | F10: =D10*E10 | G10: OccSch_Unoccupied | H10: 6 | I10: LghSch_Costant | J10: 2 | K10: EqpSch_Costant | L10: =IF(R10="Yes",Ref_Assumptions!$C$8,"–") | M10: =IF(R10="Yes",Ref_Assumptions!$C$9,"–") | N10: =IF(R10="Yes",Ref_Assumptions!$C$10,"–") | O10: 70 | P10: 40 | Q10: Always on (calibrated AHU schedules = 1) | R10: Yes | S10: =IF(R10="Yes",Ref_Assumptions!$C$2,Ref_Assumptions!$C$4) | T10: =IF(R10="Yes",Ref_Assumptions!$C$3,Ref_Assumptions!$C$4) | U10: =(F10*S10+D10*T10)*3.6 | V10: =Ref_Assumptions!$C$5 | W10: 7 | X10: 1.86004 | Y10: 18 / 15 | Z10: 20
A11: B09 | B11: debugZone7 | C11: Research laboratory – cell not clustered | D11: 43.26 | E11: 0.3 | F11: =D11*E11 | G11: OccSch_Unoccupied | H11: 6 | I11: LghSch_Costant | J11: 2 | K11: EqpSch_Costant | L11: =IF(R11="Yes",Ref_Assumptions!$C$8,"–") | M11: =IF(R11="Yes",Ref_Assumptions!$C$9,"–") | N11: =IF(R11="Yes",Ref_Assumptions!$C$10,"–") | O11: 70 | P11: 40 | Q11: Always on (calibrated AHU schedules = 1) | R11: Yes | S11: =IF(R11="Yes",Ref_Assumptions!$C$2,Ref_Assumptions!$C$4) | T11: =IF(R11="Yes",Ref_Assumptions!$C$3,Ref_Assumptions!$C$4) | U11: =(F11*S11+D11*T11)*3.6 | V11: =Ref_Assumptions!$C$5 | W11: 7 | X11: 1.80586 | Y11: 18 / 15 | Z11: 20
A12: B09 | B12: debugZone8 | C12: Research laboratory – cell not clustered | D12: 46.56 | E12: 0.3 | F12: =D12*E12 | G12: OccSch_Unoccupied | H12: 6 | I12: LghSch_Costant | J12: 2 | K12: EqpSch_Costant | L12: =IF(R12="Yes",Ref_Assumptions!$C$8,"–") | M12: =IF(R12="Yes",Ref_Assumptions!$C$9,"–") | N12: =IF(R12="Yes",Ref_Assumptions!$C$10,"–") | O12: 70 | P12: 40 | Q12: Always on (calibrated AHU schedules = 1) | R12: Yes | S12: =IF(R12="Yes",Ref_Assumptions!$C$2,Ref_Assumptions!$C$4) | T12: =IF(R12="Yes",Ref_Assumptions!$C$3,Ref_Assumptions!$C$4) | U12: =(F12*S12+D12*T12)*3.6 | V12: =Ref_Assumptions!$C$5 | W12: 7 | X12: 1.77924 | Y12: 18 / 15 | Z12: 20
A13: B09 | B13: debugZone9 | C13: Research laboratory – cell not clustered | D13: 47.26 | E13: 0.3 | F13: =D13*E13 | G13: OccSch_Unoccupied | H13: 6 | I13: LghSch_Costant | J13: 2 | K13: EqpSch_Costant | L13: =IF(R13="Yes",Ref_Assumptions!$C$8,"–") | M13: =IF(R13="Yes",Ref_Assumptions!$C$9,"–") | N13: =IF(R13="Yes",Ref_Assumptions!$C$10,"–") | O13: 70 | P13: 40 | Q13: Always on (calibrated AHU schedules = 1) | R13: Yes | S13: =IF(R13="Yes",Ref_Assumptions!$C$2,Ref_Assumptions!$C$4) | T13: =IF(R13="Yes",Ref_Assumptions!$C$3,Ref_Assumptions!$C$4) | U13: =(F13*S13+D13*T13)*3.6 | V13: =Ref_Assumptions!$C$5 | W13: 7 | X13: 1.75182 | Y13: 18 / 15 | Z13: 20
... A86: B10 | B86: zone19 | C86: Lecture hall / study room | D86: 539.86 | E86: 0.6 | F86: =D86*E86 | G86: OccSch_A0.1/A0.2 | H86: 6 | I86: LghSch_A0.1/A0.2 | J86: 10 | K86: EqpSch_A0.1/A0.2 | L86: =IF(R86="Yes",Ref_Assumptions!$C$8,"–") | M86: =IF(R86="Yes",Ref_Assumptions!$C$9,"–") | N86: =IF(R86="Yes",Ref_Assumptions!$C$10,"–") | O86: 70 | P86: 40 | Q86: Always on (calibrated AHU schedules = 1) | R86: Yes | S86: =IF(R86="Yes",Ref_Assumptions!$C$2,Ref_Assumptions!$C$4) | T86: =IF(R86="Yes",Ref_Assumptions!$C$3,Ref_Assumptions!$C$4) | U86: =(F86*S86+D86*T86)*3.6 | V86: =Ref_Assumptions!$C$5 | W86: 7 | X86: 1.56475 | Y86: 22 / 18 | Z86: 22

Sheet T7_Grouped
A1: Building | B1: Zone use | C1: N zones | D1: E+ zones | E1: Floor area (m²) | F1: Design occupants | G1: Occupancy density (person/m²) | H1: Occupancy schedule | I1: LPD (W/m²) | J1: Lighting schedule | K1: EPD (W/m²) | L1: Equipment schedule | M1: Heating SP occupied / setback (°C) | N1: Cooling SP (°C) | O1: RH max / min (%) | P1: Mech. ventilated | Q1: OA per person (L/s·p) | R1: OA per area (L/s·m²) | S1: Design OA (m³/h) | T1: Infiltration (h⁻¹)
A2: B09 | B2: Unconditioned (stairs, shafts, storage, parking) – cell not clustered | C2: 4 | D2: debugZone0, debugZone1, debugZone2, debugZone3 | E2: =SUMPRODUCT(ISNUMBER(SEARCH(", "&T7_Zones!$B$2:$B$86&",",", "&D2&","))*(T7_Zones!$A$2:$A$86=A2)*T7_Zones!$D$2:$D$86) | F2: =SUMPRODUCT(ISNUMBER(SEARCH(", "&T7_Zones!$B$2:$B$86&",",", "&D2&","))*(T7_Zones!$A$2:$A$86=A2)*T7_Zones!$F$2:$F$86) | G2: 0 | H2: OccSch_Unoccupied | I2: 6 | J2: LghSch_Costant | K2: 2 | L2: EqpSch_Costant | M2: =IF(P2="Yes",Ref_Assumptions!$C$8&" / "&Ref_Assumptions!$C$9,"–") | N2: =IF(P2="Yes",Ref_Assumptions!$C$10,"–") | O2: 70 / 40 | P2: No | Q2: =IF(P2="Yes",Ref_Assumptions!$C$2,Ref_Assumptions!$C$4) | R2: =IF(P2="Yes",Ref_Assumptions!$C$3,Ref_Assumptions!$C$4) | S2: =SUMPRODUCT(ISNUMBER(SEARCH(", "&T7_Zones!$B$2:$B$86&",",", "&D2&","))*(T7_Zones!$A$2:$A$86=A2)*T7_Zones!$U$2:$U$86) | T2: =Ref_Assumptions!$C$5
A3: B09 | B3: Research laboratory – cell not clustered | C3: 7 | D3: debugZone10, debugZone4, debugZone5, debugZone6, debugZone7, debugZone8, debugZone9 | E3: =SUMPRODUCT(ISNUMBER(SEARCH(", "&T7_Zones!$B$2:$B$86&",",", "&D3&","))*(T7_Zones!$A$2:$A$86=A3)*T7_Zones!$D$2:$D$86) | F3: =SUMPRODUCT(ISNUMBER(SEARCH(", "&T7_Zones!$B$2:$B$86&",",", "&D3&","))*(T7_Zones!$A$2:$A$86=A3)*T7_Zones!$F$2:$F$86) | G3: 0.3 | H3: OccSch_Unoccupied | I3: 6 | J3: LghSch_Costant | K3: 2 | L3: EqpSch_Costant | M3: =IF(P3="Yes",Ref_Assumptions!$C$8&" / "&Ref_Assumptions!$C$9,"–") | N3: =IF(P3="Yes",Ref_Assumptions!$C$10,"–") | O3: 70 / 40 | P3: Yes | Q3: =IF(P3="Yes",Ref_Assumptions!$C$2,Ref_Assumptions!$C$4) | R3: =IF(P3="Yes",Ref_Assumptions!$C$3,Ref_Assumptions!$C$4) | S3: =SUMPRODUCT(ISNUMBER(SEARCH(", "&T7_Zones!$B$2:$B$86&",",", "&D3&","))*(T7_Zones!$A$2:$A$86=A3)*T7_Zones!$U$2:$U$86) | T3: =Ref_Assumptions!$C$5
A4: B09 | B4: Conditioned service / circulation – cell not clustered | C4: 1 | D4: debugZone11 | E4: =SUMPRODUCT(ISNUMBER(SEARCH(", "&T7_Zones!$B$2:$B$86&",",", "&D4&","))*(T7_Zones!$A$2:$A$86=A4)*T7_Zones!$D$2:$D$86) | F4: =SUMPRODUCT(ISNUMBER(SEARCH(", "&T7_Zones!$B$2:$B$86&",",", "&D4&","))*(T7_Zones!$A$2:$A$86=A4)*T7_Zones!$F$2:$F$86) | G4: 0 | H4: OccSch_Unoccupied | I4: 6 | J4: LghSch_Costant | K4: 2 | L4: EqpSch_Costant | M4: =IF(P4="Yes",Ref_Assumptions!$C$8&" / "&Ref_Assumptions!$C$9,"–") | N4: =IF(P4="Yes",Ref_Assumptions!$C$10,"–") | O4: 70 / 40 | P4: Yes | Q4: =IF(P4="Yes",Ref_Assumptions!$C$2,Ref_Assumptions!$C$4) | R4: =IF(P4="Yes",Ref_Assumptions!$C$3,Ref_Assumptions!$C$4) | S4: =SUMPRODUCT(ISNUMBER(SEARCH(", "&T7_Zones!$B$2:$B$86&",",", "&D4&","))*(T7_Zones!$A$2:$A$86=A4)*T7_Zones!$U$2:$U$86) | T4: =Ref_Assumptions!$C$5
A5: B09 | B5: Unconditioned (stairs, shafts, storage, parking) | C5: 1 | D5: zone00 | E5: =SUMPRODUCT(ISNUMBER(SEARCH(", "&T7_Zones!$B$2:$B$86&",",", "&D5&","))*(T7_Zones!$A$2:$A$86=A5)*T7_Zones!$D$2:$D$86) | F5: =SUMPRODUCT(ISNUMBER(SEARCH(", "&T7_Zones!$B$2:$B$86&",",", "&D5&","))*(T7_Zones!$A$2:$A$86=A5)*T7_Zones!$F$2:$F$86) | G5: 0 | H5: OccSch_Unoccupied | I5: 0 | J5: LghSch_Unoccupied | K5: 0 | L5: EqpSch_Unoccupied | M5: =IF(P5="Yes",Ref_Assumptions!$C$8&" / "&Ref_Assumptions!$C$9,"–") | N5: =IF(P5="Yes",Ref_Assumptions!$C$10,"–") | O5: 100 / 0 | P5: No | Q5: =IF(P5="Yes",Ref_Assumptions!$C$2,Ref_Assumptions!$C$4) | R5: =IF(P5="Yes",Ref_Assumptions!$C$3,Ref_Assumptions!$C$4) | S5: =SUMPRODUCT(ISNUMBER(SEARCH(", "&T7_Zones!$B$2:$B$86&",",", "&D5&","))*(T7_Zones!$A$2:$A$86=A5)*T7_Zones!$U$2:$U$86) | T5: =Ref_Assumptions!$C$5
A6: B09 | B6: Unconditioned (stairs, shafts, storage, parking) | C6: 1 | D6: zone01 | E6: =SUMPRODUCT(ISNUMBER(SEARCH(", "&T7_Zones!$B$2:$B$86&",",", "&D6&","))*(T7_Zones!$A$2:$A$86=A6)*T7_Zones!$D$2:$D$86) | F6: =SUMPRODUCT(ISNUMBER(SEARCH(", "&T7_Zones!$B$2:$B$86&",",", "&D6&","))*(T7_Zones!$A$2:$A$86=A6)*T7_Zones!$F$2:$F$86) | G6: 0 | H6: OccSch_Unoccupied | I6: 6 | J6: LghSch_Costant | K6: 2 | L6: EqpSch_Costant | M6: =IF(P6="Yes",Ref_Assumptions!$C$8&" / "&Ref_Assumptions!$C$9,"–") | N6: =IF(P6="Yes",Ref_Assumptions!$C$10,"–") | O6: 70 / 40 | P6: No | Q6: =IF(P6="Yes",Ref_Assumptions!$C$2,Ref_Assumptions!$C$4) | R6: =IF(P6="Yes",Ref_Assumptions!$C$3,Ref_Assumptions!$C$4) | S6: =SUMPRODUCT(ISNUMBER(SEARCH(", "&T7_Zones!$B$2:$B$86&",",", "&D6&","))*(T7_Zones!$A$2:$A$86=A6)*T7_Zones!$U$2:$U$86) | T6: =Ref_Assumptions!$C$5
A7: B09 | B7: Conditioned service / circulation | C7: 5 | D7: zone02, zone05, zone12-0, zone12-2, zone29 | E7: =SUMPRODUCT(ISNUMBER(SEARCH(", "&T7_Zones!$B$2:$B$86&",",", "&D7&","))*(T7_Zones!$A$2:$A$86=A7)*T7_Zones!$D$2:$D$86) | F7: =SUMPRODUCT(ISNUMBER(SEARCH(", "&T7_Zones!$B$2:$B$86&",",", "&D7&","))*(T7_Zones!$A$2:$A$86=A7)*T7_Zones!$F$2:$F$86) | G7: 0 | H7: OccSch_Unoccupied | I7: 6 | J7: LghSch_Costant | K7: 2 | L7: EqpSch_Costant | M7: =IF(P7="Yes",Ref_Assumptions!$C$8&" / "&Ref_Assumptions!$C$9,"–") | N7: =IF(P7="Yes",Ref_Assumptions!$C$10,"–") | O7: 70 / 40 | P7: Yes | Q7: =IF(P7="Yes",Ref_Assumptions!$C$2,Ref_Assumptions!$C$4) | R7: =IF(P7="Yes",Ref_Assumptions!$C$3,Ref_Assumptions!$C$4) | S7: =SUMPRODUCT(ISNUMBER(SEARCH(", "&T7_Zones!$B$2:$B$86&",",", "&D7&","))*(T7_Zones!$A$2:$A$86=A7)*T7_Zones!$U$2:$U$86) | T7: =Ref_Assumptions!$C$5
A8: B09 | B8: Unconditioned (stairs, shafts, storage, parking) | C8: 6 | D8: zone03, zone04, zone10, zone12-1, zone13, zone14 | E8: =SUMPRODUCT(ISNUMBER(SEARCH(", "&T7_Zones!$B$2:$B$86&",",", "&D8&","))*(T7_Zones!$A$2:$A$86=A8)*T7_Zones!$D$2:$D$86) | F8: =SUMPRODUCT(ISNUMBER(SEARCH(", "&T7_Zones!$B$2:$B$86&",",", "&D8&","))*(T7_Zones!$A$2:$A$86=A8)*T7_Zones!$F$2:$F$86) | G8: 0 | H8: OccSch_Unoccupied | I8: 6 | J8: AlwaysOff | K8: 0 | L8: AlwaysOff | M8: =IF(P8="Yes",Ref_Assumptions!$C$8&" / "&Ref_Assumptions!$C$9,"–") | N8: =IF(P8="Yes",Ref_Assumptions!$C$10,"–") | O8: 70 / 40 | P8: No | Q8: =IF(P8="Yes",Ref_Assumptions!$C$2,Ref_Assumptions!$C$4) | R8: =IF(P8="Yes",Ref_Assumptions!$C$3,Ref_Assumptions!$C$4) | S8: =SUMPRODUCT(ISNUMBER(SEARCH(", "&T7_Zones!$B$2:$B$86&",",", "&D8&","))*(T7_Zones!$A$2:$A$86=A8)*T7_Zones!$U$2:$U$86) | T8: =Ref_Assumptions!$C$5
A9: B09 | B9: Conditioned service / circulation | C9: 1 | D9: zone06 | E9: =SUMPRODUCT(ISNUMBER(SEARCH(", "&T7_Zones!$B$2:$B$86&",",", "&D9&","))*(T7_Zones!$A$2:$A$86=A9)*T7_Zones!$D$2:$D$86) | F9: =SUMPRODUCT(ISNUMBER(SEARCH(", "&T7_Zones!$B$2:$B$86&",",", "&D9&","))*(T7_Zones!$A$2:$A$86=A9)*T7_Zones!$F$2:$F$86) | G9: 0 | H9: OccSch_Unoccupied | I9: 6 | J9: AlwaysOff | K9: 0 | L9: AlwaysOff | M9: =IF(P9="Yes",Ref_Assumptions!$C$8&" / "&Ref_Assumptions!$C$9,"–") | N9: =IF(P9="Yes",Ref_Assumptions!$C$10,"–") | O9: 70 / 40 | P9: Yes | Q9: =IF(P9="Yes",Ref_Assumptions!$C$2,Ref_Assumptions!$C$4) | R9: =IF(P9="Yes",Ref_Assumptions!$C$3,Ref_Assumptions!$C$4) | S9: =SUMPRODUCT(ISNUMBER(SEARCH(", "&T7_Zones!$B$2:$B$86&",",", "&D9&","))*(T7_Zones!$A$2:$A$86=A9)*T7_Zones!$U$2:$U$86) | T9: =Ref_Assumptions!$C$5
A10: B09 | B10: Unconditioned (stairs, shafts, storage, parking) | C10: 1 | D10: zone07 | E10: =SUMPRODUCT(ISNUMBER(SEARCH(", "&T7_Zones!$B$2:$B$86&",",", "&D10&","))*(T7_Zones!$A$2:$A$86=A10)*T7_Zones!$D$2:$D$86) | F10: =SUMPRODUCT(ISNUMBER(SEARCH(", "&T7_Zones!$B$2:$B$86&",",", "&D10&","))*(T7_Zones!$A$2:$A$86=A10)*T7_Zones!$F$2:$F$86) | G10: 0 | H10: OccSch_Unoccupied | I10: 6 | J10: AlwaysOff | K10: 2 | L10: AlwaysOff | M10: =IF(P10="Yes",Ref_Assumptions!$C$8&" / "&Ref_Assumptions!$C$9,"–") | N10: =IF(P10="Yes",Ref_Assumptions!$C$10,"–") | O10: 70 / 40 | P10: No | Q10: =IF(P10="Yes",Ref_Assumptions!$C$2,Ref_Assumptions!$C$4) | R10: =IF(P10="Yes",Ref_Assumptions!$C$3,Ref_Assumptions!$C$4) | S10: =SUMPRODUCT(ISNUMBER(SEARCH(", "&T7_Zones!$B$2:$B$86&",",", "&D10&","))*(T7_Zones!$A$2:$A$86=A10)*T7_Zones!$U$2:$U$86) | T10: =Ref_Assumptions!$C$5
A11: B09 | B11: Conditioned service / circulation | C11: 1 | D11: zone08 | E11: =SUMPRODUCT(ISNUMBER(SEARCH(", "&T7_Zones!$B$2:$B$86&",",", "&D11&","))*(T7_Zones!$A$2:$A$86=A11)*T7_Zones!$D$2:$D$86) | F11: =SUMPRODUCT(ISNUMBER(SEARCH(", "&T7_Zones!$B$2:$B$86&",",", "&D11&","))*(T7_Zones!$A$2:$A$86=A11)*T7_Zones!$F$2:$F$86) | G11: 0 | H11: OccSch_Unoccupied | I11: 6 | J11: AlwaysOff | K11: 2 | L11: AlwaysOff | M11: =IF(P11="Yes",Ref_Assumptions!$C$8&" / "&Ref_Assumptions!$C$9,"–") | N11: =IF(P11="Yes",Ref_Assumptions!$C$10,"–") | O11: 70 / 40 | P11: Yes | Q11: =IF(P11="Yes",Ref_Assumptions!$C$2,Ref_Assumptions!$C$4) | R11: =IF(P11="Yes",Ref_Assumptions!$C$3,Ref_Assumptions!$C$4) | S11: =SUMPRODUCT(ISNUMBER(SEARCH(", "&T7_Zones!$B$2:$B$86&",",", "&D11&","))*(T7_Zones!$A$2:$A$86=A11)*T7_Zones!$U$2:$U$86) | T11: =Ref_Assumptions!$C$5
A12: B09 | B12: Lecture hall / study room | C12: 2 | D12: zone09, zone30 | E12: =SUMPRODUCT(ISNUMBER(SEARCH(", "&T7_Zones!$B$2:$B$86&",",", "&D12&","))*(T7_Zones!$A$2:$A$86=A12)*T7_Zones!$D$2:$D$86) | F12: =SUMPRODUCT(ISNUMBER(SEARCH(", "&T7_Zones!$B$2:$B$86&",",", "&D12&","))*(T7_Zones!$A$2:$A$86=A12)*T7_Zones!$F$2:$F$86) | G12: 0.6 | H12: OccSch_Unoccupied | I12: 6 | J12: LghSch_Costant | K12: 2 | L12: EqpSch_Costant | M12: =IF(P12="Yes",Ref_Assumptions!$C$8&" / "&Ref_Assumptions!$C$9,"–") | N12: =IF(P12="Yes",Ref_Assumptions!$C$10,"–") | O12: 70 / 40 | P12: Yes | Q12: =IF(P12="Yes",Ref_Assumptions!$C$2,Ref_Assumptions!$C$4) | R12: =IF(P12="Yes",Ref_Assumptions!$C$3,Ref_Assumptions!$C$4) | S12: =SUMPRODUCT(ISNUMBER(SEARCH(", "&T7_Zones!$B$2:$B$86&",",", "&D12&","))*(T7_Zones!$A$2:$A$86=A12)*T7_Zones!$U$2:$U$86) | T12: =Ref_Assumptions!$C$5
A13: B09 | B13: Office | C13: 1 | D13: zone11 | E13: =SUMPRODUCT(ISNUMBER(SEARCH(", "&T7_Zones!$B$2:$B$86&",",", "&D13&","))*(T7_Zones!$A$2:$A$86=A13)*T7_Zones!$D$2:$D$86) | F13: =SUMPRODUCT(ISNUMBER(SEARCH(", "&T7_Zones!$B$2:$B$86&",",", "&D13&","))*(T7_Zones!$A$2:$A$86=A13)*T7_Zones!$F$2:$F$86) | G13: 0.12 | H13: OccSch_Unoccupied | I13: 7 | J13: LghSch_Costant | K13: 2 | L13: EqpSch_Costant | M13: =IF(P13="Yes",Ref_Assumptions!$C$8&" / "&Ref_Assumptions!$C$9,"–") | N13: =IF(P13="Yes",Ref_Assumptions!$C$10,"–") | O13: 70 / 40 | P13: Yes | Q13: =IF(P13="Yes",Ref_Assumptions!$C$2,Ref_Assumptions!$C$4) | R13: =IF(P13="Yes",Ref_Assumptions!$C$3,Ref_Assumptions!$C$4) | S13: =SUMPRODUCT(ISNUMBER(SEARCH(", "&T7_Zones!$B$2:$B$86&",",", "&D13&","))*(T7_Zones!$A$2:$A$86=A13)*T7_Zones!$U$2:$U$86) | T13: =Ref_Assumptions!$C$5
... A26: B10 | B26: Lecture hall / study room | C26: 4 | D26: zone15, zone16, zone18, zone19 | E26: =SUMPRODUCT(ISNUMBER(SEARCH(", "&T7_Zones!$B$2:$B$86&",",", "&D26&","))*(T7_Zones!$A$2:$A$86=A26)*T7_Zones!$D$2:$D$86) | F26: =SUMPRODUCT(ISNUMBER(SEARCH(", "&T7_Zones!$B$2:$B$86&",",", "&D26&","))*(T7_Zones!$A$2:$A$86=A26)*T7_Zones!$F$2:$F$86) | G26: 0.6 | H26: OccSch_<room> (lecture timetable) | I26: 6 | J26: LghSch_<room> (lecture timetable) | K26: 10 | L26: EqpSch_<room> (lecture timetable) | M26: =IF(P26="Yes",Ref_Assumptions!$C$8&" / "&Ref_Assumptions!$C$9,"–") | N26: =IF(P26="Yes",Ref_Assumptions!$C$10,"–") | O26: 70 / 40 | P26: Yes | Q26: =IF(P26="Yes",Ref_Assumptions!$C$2,Ref_Assumptions!$C$4) | R26: =IF(P26="Yes",Ref_Assumptions!$C$3,Ref_Assumptions!$C$4) | S26: =SUMPRODUCT(ISNUMBER(SEARCH(", "&T7_Zones!$B$2:$B$86&",",", "&D26&","))*(T7_Zones!$A$2:$A$86=A26)*T7_Zones!$U$2:$U$86) | T26: =Ref_Assumptions!$C$5

Sheet T8_Envelope
A1: Construction | B1: Envelope role | C1: Include in paper | D1: Source | E1: N layers | F1: Layers outside → inside: material, thickness (λ W/m·K; ρ kg/m³; c J/kg·K) | G1: Layer data from | H1: Total thickness (m) | I1: R layers (m²K/W) | J1: Rsi (m²K/W) | K1: Rse (m²K/W) | L1: U (W/m²K) | M1: B09 net opaque area (m²) | N1: B09 N surfaces | O1: B10 net opaque area (m²) | P1: B10 N surfaces
A2: WL_POLIMI-LC_EW01 | B2: External wall | C2: Yes | D2: IFC IfcMaterialLayerSet | E2: 8 | F2: Pannello in alluminio 0.5 cm (λ 220; ρ 2700; c 896) | Camera d'aria fortemente ventilata 3.5 cm (λ 0.285; ρ 1; c 1004) | Isolante rigido 6 cm (λ 0.04; ρ 30; c 1452) | Membrana impermeabilizzante 0.5 cm (λ 0.23; ρ 1100; c 1000) | Camera d'aria debolmente ventilata 20 cm (λ 1; ρ 1; c 1004) | Isolante morbido 6.5 cm (λ 0.04; ρ 80; c 1028) | Gypsum Board 2.5 cm (λ 0.21; ρ 900; c 1000) | Intonaco interno 1 cm (λ 0.35; ρ 1200; c 999) | G2: B09 | H2: =SUMIFS(Val_Layers!$F$2:$F$220,Val_Layers!$A$2:$A$220,G2,Val_Layers!$B$2:$B$220,A2) | I2: =SUMIFS(Val_Layers!$N$2:$N$220,Val_Layers!$A$2:$A$220,G2,Val_Layers!$B$2:$B$220,A2) | J2: 0.13 | K2: 0.04 | L2: =1/(J2+I2+K2) | M2: 89.5 | N2: 3 | O2: 98.6 | P2: 3
A3: WL_POLIMI-LC_EW02 | B3: External wall | C3: Yes | D3: IFC IfcMaterialLayerSet; also fallback for unmatched exterior faces | E3: 8 | F3: Pannello in alluminio 0.5 cm (λ 220; ρ 2700; c 896) | Camera d'aria fortemente ventilata 3.5 cm (λ 0.285; ρ 1; c 1004) | Isolante rigido 10 cm (λ 0.04; ρ 30; c 1452) | Membrana impermeabilizzante 0.5 cm (λ 0.23; ρ 1100; c 1000) | Camera d'aria debolmente ventilata 26 cm (λ 1; ρ 1; c 1004) | Isolante morbido 6.5 cm (λ 0.04; ρ 80; c 1028) | Gypsum Board 2.5 cm (λ 0.21; ρ 900; c 1000) | Intonaco interno 1 cm (λ 0.35; ρ 1200; c 999) | G3: B09 | H3: =SUMIFS(Val_Layers!$F$2:$F$220,Val_Layers!$A$2:$A$220,G3,Val_Layers!$B$2:$B$220,A3) | I3: =SUMIFS(Val_Layers!$N$2:$N$220,Val_Layers!$A$2:$A$220,G3,Val_Layers!$B$2:$B$220,A3) | J3: 0.13 | K3: 0.04 | L3: =1/(J3+I3+K3) | M3: 2427.6 | N3: 156 | O3: 531.9 | P3: 33
A4: WL_POLIMI-LC_EW03 | B4: External wall | C4: Yes | D4: IFC IfcMaterialLayerSet | E4: 9 | F4: Pannello in alluminio 0.5 cm (λ 220; ρ 2700; c 896) | Camera d'aria fortemente ventilata 3.5 cm (λ 0.285; ρ 1; c 1004) | Isolante rigido 10 cm (λ 0.04; ρ 30; c 1452) | Membrana impermeabilizzante 0.5 cm (λ 0.23; ρ 1100; c 1000) | Camera d'aria debolmente ventilata 26.5 cm (λ 1; ρ 1; c 1004) | CLS 42.5 cm (λ 1.046; ρ 2300; c 657) | Isolante morbido 6.5 cm (λ 0.04; ρ 80; c 1028) | Gypsum Board 2.5 cm (λ 0.21; ρ 900; c 1000) | Intonaco interno 1 cm (λ 0.35; ρ 1200; c 999) | G4: B09 | H4: =SUMIFS(Val_Layers!$F$2:$F$220,Val_Layers!$A$2:$A$220,G4,Val_Layers!$B$2:$B$220,A4) | I4: =SUMIFS(Val_Layers!$N$2:$N$220,Val_Layers!$A$2:$A$220,G4,Val_Layers!$B$2:$B$220,A4) | J4: 0.13 | K4: 0.04 | L4: =1/(J4+I4+K4) | M4: 179.4 | N4: 13 | O4: 214 | P4: 8
A5: WL_POLIMI-LC_EW04 | B5: External wall | C5: Yes | D5: IFC IfcMaterialLayerSet | E5: 7 | F5: Pannello in alluminio 0.5 cm (λ 220; ρ 2700; c 896) | Camera d'aria fortemente ventilata 3.5 cm (λ 0.285; ρ 1; c 1004) | Isolante rigido 10 cm (λ 0.04; ρ 30; c 1452) | Membrana impermeabilizzante 0.5 cm (λ 0.23; ρ 1100; c 1000) | Camera d'aria debolmente ventilata 26.5 cm (λ 1; ρ 1; c 1004) | CLS 42.5 cm (λ 1.046; ρ 2300; c 657) | Intonaco interno 1 cm (λ 0.35; ρ 1200; c 999) | G5: B09 | H5: =SUMIFS(Val_Layers!$F$2:$F$220,Val_Layers!$A$2:$A$220,G5,Val_Layers!$B$2:$B$220,A5) | I5: =SUMIFS(Val_Layers!$N$2:$N$220,Val_Layers!$A$2:$A$220,G5,Val_Layers!$B$2:$B$220,A5) | J5: 0.13 | K5: 0.04 | L5: =1/(J5+I5+K5) | M5: 250.3 | N5: 11 | O5: 12.3 | P5: 1
A6: WL_POLIMI-LC_EW05 | B6: External wall | C6: Yes | D6: IFC IfcMaterialLayerSet | E6: 9 | F6: Pannello in alluminio 0.5 cm (λ 220; ρ 2700; c 896) | Camera d'aria fortemente ventilata 3.5 cm (λ 0.285; ρ 1; c 1004) | Isolante rigido 10 cm (λ 0.04; ρ 30; c 1452) | Membrana impermeabilizzante 0.5 cm (λ 0.23; ρ 1100; c 1000) | Camera d'aria debolmente ventilata 26.5 cm (λ 1; ρ 1; c 1004) | Camera d'aria fortemente ventilata 42.5 cm (λ 0.285; ρ 1; c 1004) | Isolante morbido 6.5 cm (λ 0.04; ρ 80; c 1028) | Gypsum Board 2.5 cm (λ 0.21; ρ 900; c 1000) | Intonaco interno 1 cm (λ 0.35; ρ 1200; c 999) | G6: B09 | H6: =SUMIFS(Val_Layers!$F$2:$F$220,Val_Layers!$A$2:$A$220,G6,Val_Layers!$B$2:$B$220,A6) | I6: =SUMIFS(Val_Layers!$N$2:$N$220,Val_Layers!$A$2:$A$220,G6,Val_Layers!$B$2:$B$220,A6) | J6: 0.13 | K6: 0.04 | L6: =1/(J6+I6+K6) | M6: 493.4 | N6: 34 | O6: 108 | P6: 2
A7: WL_POLIMI-LC_FC300 | B7: External wall | C7: Yes | D7: IFC IfcMaterialLayerSet | E7: 3 | F7: Intonaco interno 1.5 cm (λ 0.35; ρ 1200; c 999) | Calcestruzzo- gettato in opera 26 cm (λ 1.046; ρ 2300; c 657) | Intonaco interno 1.5 cm (λ 0.35; ρ 1200; c 999) | G7: B10 | H7: =SUMIFS(Val_Layers!$F$2:$F$220,Val_Layers!$A$2:$A$220,G7,Val_Layers!$B$2:$B$220,A7) | I7: =SUMIFS(Val_Layers!$N$2:$N$220,Val_Layers!$A$2:$A$220,G7,Val_Layers!$B$2:$B$220,A7) | J7: 0.13 | K7: 0.04 | L7: =1/(J7+I7+K7) | M7: 0 | N7: 0 | O7: 190.2 | P7: 15
A8: WL_POLIMI-LC_FC300-2 | B8: External wall | C8: Yes | D8: IFC IfcMaterialLayerSet | E8: 5 | F8: Intonaco interno 1.5 cm (λ 0.35; ρ 1200; c 999) | Calcestruzzo- gettato in opera 26 cm (λ 1.046; ρ 2300; c 657) | Isolante morbido 6.5 cm (λ 0.04; ρ 80; c 1028) | Gypsum Board 2.5 cm (λ 0.21; ρ 900; c 1000) | Intonaco interno 1 cm (λ 0.35; ρ 1200; c 999) | G8: B09 | H8: =SUMIFS(Val_Layers!$F$2:$F$220,Val_Layers!$A$2:$A$220,G8,Val_Layers!$B$2:$B$220,A8) | I8: =SUMIFS(Val_Layers!$N$2:$N$220,Val_Layers!$A$2:$A$220,G8,Val_Layers!$B$2:$B$220,A8) | J8: 0.13 | K8: 0.04 | L8: =1/(J8+I8+K8) | M8: 1131.6 | N8: 48 | O8: 0 | P8: 0
A9: WL_POLIMI-LC_FC300-3 | B9: External wall | C9: Yes | D9: IFC IfcMaterialLayerSet | E9: 8 | F9: Intonaco interno 1.5 cm (λ 0.35; ρ 1200; c 999) | Gypsum Board 2.5 cm (λ 0.21; ρ 900; c 1000) | Isolante morbido 10 cm (λ 0.04; ρ 80; c 1028) | Camera d'aria debolmente ventilata 15 cm (λ 1; ρ 1; c 1004) | Calcestruzzo- gettato in opera 26 cm (λ 1.046; ρ 2300; c 657) | Isolante morbido 6.5 cm (λ 0.04; ρ 80; c 1028) | Gypsum Board 2.5 cm (λ 0.21; ρ 900; c 1000) | Intonaco interno 1 cm (λ 0.35; ρ 1200; c 999) | G9: B09 | H9: =SUMIFS(Val_Layers!$F$2:$F$220,Val_Layers!$A$2:$A$220,G9,Val_Layers!$B$2:$B$220,A9) | I9: =SUMIFS(Val_Layers!$N$2:$N$220,Val_Layers!$A$2:$A$220,G9,Val_Layers!$B$2:$B$220,A9) | J9: 0.13 | K9: 0.04 | L9: =1/(J9+I9+K9) | M9: 4.8 | N9: 1 | O9: 0 | P9: 0
A10: RF_POLIMI-LC_IH-E | B10: Roof | C10: Yes | D10: Notebook (manual layers) | E10: 4 | F10: Ghiaia 8 cm (λ 1.2; ρ 1700; c 1000) | Massetto 12 cm (λ 1.2; ρ 1700; c 1000) | Isolante rigido 8 cm (λ 0.04; ρ 30; c 1452) | CLS 25 cm (λ 1.046; ρ 2300; c 657) | G10: B09 | H10: =SUMIFS(Val_Layers!$F$2:$F$220,Val_Layers!$A$2:$A$220,G10,Val_Layers!$B$2:$B$220,A10) | I10: =SUMIFS(Val_Layers!$N$2:$N$220,Val_Layers!$A$2:$A$220,G10,Val_Layers!$B$2:$B$220,A10) | J10: 0.1 | K10: 0.04 | L10: =1/(J10+I10+K10) | M10: 4003 | N10: 52 | O10: 1590.2 | P10: 17
A11: FL_POLIMI-LC_GroundFloor | B11: Ground floor | C11: Yes | D11: IFC IfcMaterialLayerSet | E11: 7 | F11: Pavimento industriale 6 cm (λ 1.046; ρ 2300; c 657) | Massetto 8 cm (λ 1.2; ρ 1700; c 1000) | Isolante rigido 6 cm (λ 0.04; ρ 30; c 1452) | CLS 5 cm (λ 1.046; ρ 2300; c 657) | Camera d'aria fortemente ventilata 35 cm (λ 0.285; ρ 1; c 1004) | Magrone 10 cm (λ 1.046; ρ 2300; c 657) | Ghiaia 20 cm (λ 1.2; ρ 1700; c 1000) | G11: B09 | H11: =SUMIFS(Val_Layers!$F$2:$F$220,Val_Layers!$A$2:$A$220,G11,Val_Layers!$B$2:$B$220,A11) | I11: =SUMIFS(Val_Layers!$N$2:$N$220,Val_Layers!$A$2:$A$220,G11,Val_Layers!$B$2:$B$220,A11) | J11: 0.17 | K11: 0 | L11: =1/(J11+I11+K11) | M11: 2621.2 | N11: 46 | O11: 196.9 | P11: 15
A12: Generic Ground Slab | B12: Ground floor | C12: Yes | D12: HB default (no BIM match) | E12: 2 | F12: Generic 50mm Insulation 5 cm (λ 0.03; ρ 43; c 1210) | Generic HW Concrete 20 cm (λ 1.95; ρ 2240; c 900) | G12: B09 | H12: =SUMIFS(Val_Layers!$F$2:$F$220,Val_Layers!$A$2:$A$220,G12,Val_Layers!$B$2:$B$220,A12) | I12: =SUMIFS(Val_Layers!$N$2:$N$220,Val_Layers!$A$2:$A$220,G12,Val_Layers!$B$2:$B$220,A12) | J12: 0.17 | K12: 0 | L12: =1/(J12+I12+K12) | M12: 1381.7 | N12: 1 | O12: 0 | P12: 0
A13: FL_POLIMI-LC_InternalFloor_IH-E | B13: Floor over outdoor/unheated | C13: Yes | D13: IFC IfcMaterialLayerSet | E13: 5 | F13: Linoleum 1 cm (λ 0.041; ρ 50; c 2301) | Massetto 15 cm (λ 1.2; ρ 1700; c 1000) | Isolante rigido 10 cm (λ 0.04; ρ 30; c 1452) | Solaio laterocemento 15 cm (λ 0.66; ρ 1100; c 839) | Intonaco interno 2 cm (λ 0.35; ρ 1200; c 999) | G13: B10 | H13: =SUMIFS(Val_Layers!$F$2:$F$220,Val_Layers!$A$2:$A$220,G13,Val_Layers!$B$2:$B$220,A13) | I13: =SUMIFS(Val_Layers!$N$2:$N$220,Val_Layers!$A$2:$A$220,G13,Val_Layers!$B$2:$B$220,A13) | J13: 0.17 | K13: 0.04 | L13: =1/(J13+I13+K13) | M13: 0 | N13: 0 | O13: 1393.3 | P13: 13
... A19: WL_POLIMI-LC_IW06_Toilet | B19: Internal partition exposed to outdoors (adjacent cell excluded from BEM) | C19: No | D19: IFC IfcMaterialLayerSet | E19: 5 | F19: Camera d'aria non ventilata 6.5 cm (λ 1; ρ 1; c 1003) | Isolante morbido 4 cm (λ 0.04; ρ 80; c 1028) | Gypsum Board 2.5 cm (λ 0.21; ρ 900; c 1000) | Intonaco gesso puro 1 cm (λ 0.35; ρ 1200; c 999) | Piastrelle 1.5 cm (λ 1.3; ρ 2300; c 839) | G19: B09 | H19: =SUMIFS(Val_Layers!$F$2:$F$220,Val_Layers!$A$2:$A$220,G19,Val_Layers!$B$2:$B$220,A19) | I19: =SUMIFS(Val_Layers!$N$2:$N$220,Val_Layers!$A$2:$A$220,G19,Val_Layers!$B$2:$B$220,A19) | J19: 0.13 | K19: 0.13 | L19: =1/(J19+I19+K19) | M19: 295.6 | N19: 21 | O19: 85.2 | P19: 4

Sheet T9_Glazing
A1: Construction | B1: Element | C1: E+ model | D1: U (W/m²K) | E1: SHGC | F1: VT | G1: Glass layers (BIM) | H1: Glass U (BIM, W/m²K) | I1: Frame material (BIM) | J1: Frame U (BIM, W/m²K) | K1: Glazing area fraction (BIM) | L1: Glazed fraction in BEM | M1: B09 N surfaces | N1: B09 area (m²) | O1: B09 with ext. blind | P1: B10 N surfaces | Q1: B10 area (m²) | R1: B10 with ext. blind | S1: Note
A2: windowConstruction_U0.9_SHGC0.67_VT0.8 | B2: Window / glazed door (IfcWindow, IfcDoor) | C2: WindowMaterial:SimpleGlazingSystem | D2: 0.9 | E2: 0.67 | F2: 0.8 | G2: Double | H2: 1.1 | I2: Aluminium | J2: 0.7 | K2: 0.8 | L2: geometry of the aperture | M2: 1 | N2: 3.8 | O2: 0 | P2: 2 | Q2: 23 | R2: 1
A3: curtainWallWindowConstruction_U0.9_SHGC0.67_VT0.8 | B3: Curtain wall (IfcWall CurtainWall / CurtainWall150) | C3: WindowMaterial:SimpleGlazingSystem | D3: 0.9 | E3: 0.67 | F3: 0.8 | G3: Double | H3: 1.1 | I3: Aluminium | J3: 0.7 | K3: 0.8 | L3: 0.81 (face scaled 0.9 × 0.9) | M3: 31 | N3: 1061 | O3: 11 | P3: 12 | Q3: 611.3 | R3: 1
A4: windowConstruction_U0.9_SHGC0.67_VT0.58 | B4: Window / glazed door (IfcWindow, IfcDoor) | C4: WindowMaterial:SimpleGlazingSystem | D4: 0.9 | E4: 0.67 | F4: 0.58 | G4: Double | H4: 1.1 | I4: Aluminium | J4: 0.7 | K4: 0.8 | L4: geometry of the aperture | M4: 0 | N4: 0 | O4: 0 | P4: 2 | Q4: 7.6 | R4: 0
A5: curtainWallWindowConstruction_U0.9_SHGC0.67_VT0.58 | B5: Curtain wall (IfcWall CurtainWall / CurtainWall150) | C5: WindowMaterial:SimpleGlazingSystem | D5: 0.9 | E5: 0.67 | F5: 0.58 | G5: Double | H5: 1.1 | I5: Aluminium | J5: 0.7 | K5: 0.8 | L5: 0.81 (face scaled 0.9 × 0.9) | M5: 23 | N5: 841.5 | O5: 0 | P5: 9 | Q5: 478.8 | R5: 2 | S5: B09: 23 curtain-wall panels (841.5 m²) have BIM VT 0.58 but kept HB 'Generic Double Pane' in the IDF; reported here with their BIM glazing properties (author decision, table only).

Sheet Map_Spaces
A1: ID | B1: Paper table | C1: Paper property name | D1: Topologic entity | E1: Topologic key | F1: IFC entity | G1: IFC pset | H1: IFC property | I1: Read by workflow from | J1: BIM unit | K1: Cell → zone aggregation | L1: Honeybee object | M1: Honeybee attribute | N1: EnergyPlus object | O1: EnergyPlus field | P1: E+ unit | Q1: Conversion BIM → E+ | R1: Default if missing / 'Undefined' | S1: In IDF? | T1: Implementation | U1: Value B09 (BIM) | V1: Value B10 (BIM) | W1: Value in IDF – baseline | X1: Value in IDF – calibrated | Y1: Notes
A2: S01 | B2: T7 | C2: Occupancy Type | D2: Cell | E2: pr_OccupancyType | F2: IfcSpace | G2: Altro (B09) / Other (B10) | H2: pr_OccupancyType | I2: Topologic JSON | J2: text | K2: Prevalent: type of the cell with the largest occupant count (density × area) | L2: Room | M2: properties.energy.program_type (fixed: honeybee_energy office_program, not mapped) | N2: People / Lights / ElectricEquipment / ZoneInfiltration:DesignFlowRate | O2: Name (prefix 'Generic Office …' inherited from HB office program) | P2: – | Q2: none | R2: 'StorageSpaces:GeneralStorageSpace' (cell, B09 nb); 'FacilityServiceSpaces:Corridor' if zone type contains 'Default' (B09 nb) | S2: No | T2: Utils.TopologicZoneInheritSpaceData (Operation.py:4); TBIM.Cells_ClusterizeIntoEnergyZones | U2: FacilityServiceSpaces:HorizontalInfrastructure/ServiceSpaceNon-Occupied (×56); EducationandTrainingSpaces:Research/Non-ClassClassLaboratory (×23); EducationandTrainingSpaces:LectureHall(FixedSeats) (×19); FacilityServiceSpaces:UtilityEquipmentRoom (×13); FacilityServiceSpaces:ElevatorShaft (×12); FacilityServiceSpaces:Restroom (×12); FacilityServiceSpaces:Stairway (×9); FacilityServiceSpaces:Corridor (×8); StorageSpaces:GeneralStorageSpace (×1); EducationandTrainingSpaces:StudyRoom (×1); CommerceActivitySpaces:OfficeSpaces (×1) | V2: FacilityServiceSpaces:Corridor (×8); FacilityServiceSpaces:HorizontalInfrastructure/ServiceSpaceNon-Occupied (×8); FacilityServiceSpaces:Restroom (×7); FacilityServiceSpaces:Stairway (×5); FacilityServiceSpaces:ElevatorShaft (×5); EducationandTrainingSpaces:LectureHall(FixedSeats) (×4); ParkingSpaces:InteriorParkingSpaces (×3); FacilityServiceSpaces:UtilityEquipmentRoom (×3); StorageSpaces:GeneralStorageSpace (×3); ServiceActivitySpaces:SnackBar (×1); EducationandTrainingSpaces:Research/Non-ClassClassLaboratory (×1); ProtectiveSpaces:EntryPorch (×1) | W2: not written | X2: not written | Y2: Used only to build zones: single-cell zones for lecture halls, labs, storage; stairs/elevators merged with adjacent corridor; horizontal infrastructure merged with corridor/stair/restroom.
A3: S02 | B3: T7 | C3: Is Occupied | D3: Cell | E3: pr_IsOccupied | F3: IfcSpace | G3: Altro (B09) / Other (B10) | H3: pr_IsOccupied | I3: Topologic JSON | J3: bool (0/1) | K3: Logical OR | L3: – | M3: – | N3: – | O3: – | P3: – | Q3: none | R3: 0 | S3: No | T3: TBIM.Cells_ClusterizeIntoEnergyZones (K-Means feature) | U3: 0 / 1 | V3: 0 / 1 | W3: – | X3: – | Y3: K-Means feature (standardised).
A4: S03 | B4: T7 | C4: Is Heated | D4: Cell | E4: pr_IsHeated | F4: IfcSpace | G4: Altro (B09) / Other (B10) | H4: pr_IsHeated | I4: Topologic JSON | J4: bool (0/1) | K4: Logical OR | L4: – | M4: – | N4: – | O4: – | P4: – | Q4: none | R4: 0 | S4: No | T4: TBIM.Cells_ClusterizeIntoEnergyZones (K-Means feature) | U4: 0 / 1 | V4: 0 / 1 | W4: – | X4: – | Y4: Heating availability in E+ comes from rl_IsScheduledBy_Heating (S29), not from this flag.
A5: S04 | B5: T7 | C5: Is Cooled | D5: Cell | E5: pr_IsCooled | F5: IfcSpace | G5: Altro (B09) / Other (B10) | H5: pr_IsCooled | I5: Topologic JSON | J5: bool (0/1) | K5: Logical OR | L5: – | M5: – | N5: – | O5: – | P5: – | Q5: none | R5: 0 | S5: No | T5: TBIM.Cells_ClusterizeIntoEnergyZones (K-Means feature) | U5: 0 / 1 | V5: 0 / 1 | W5: – | X5: – | Y5: Cooling availability in E+ comes from rl_IsScheduledBy_Cooling (S30).
A6: S05 | B6: T7 | C6: Is Mechanically Ventilated | D6: Cell | E6: pr_IsMechanicallyVentilated | F6: IfcSpace | G6: Altro (B09) / Other (B10) | H6: pr_IsMechanicallyVentilated | I6: Topologic JSON | J6: bool (0/1) | K6: Logical OR (stored on zone) | L6: – | M6: – | N6: – | O6: – | P6: – | Q6: none | R6: – | S6: No | T6: Utils.TopologicZoneInheritSpaceData (Operation.py:4) | U6: 0 / 1 | V6: 0 / 1 | W6: – | X6: – | Y6: TBIM also contains a duplicate key 'pr_IsMechanicalVentilated'.
A7: S06 | B7: T7 | C7: Is Naturally Ventilated | D7: Cell | E7: pr_IsNaturallyVentilated | F7: IfcSpace | G7: Altro (B09) / Other (B10) | H7: pr_IsNaturallyVentilated | I7: not read | J7: bool (0/1) | K7: – | L7: – | M7: – | N7: – | O7: – | P7: – | Q7: – | R7: – | S7: No | T7: – | U7: 0 | V7: 0 / 1 | W7: – | X7: – | Y7: No natural-ventilation object (ZoneVentilation) is generated.
A8: S07 | B8: T7 | C8: Artificial Lighting | D8: Cell | E8: pr_ArtificialLighting | F8: IfcSpace | G8: Altro (B09) / Other (B10) | H8: pr_ArtificialLighting | I8: not read | J8: bool (0/1) | K8: – | L8: – | M8: – | N8: – | O8: – | P8: – | Q8: – | R8: – | S8: No | T8: – | U8: 1 | V8: 1 | W8: – | X8: –
A9: S08 | B9: T7 | C9: Illuminance | D9: Cell | E9: pr_Illuminance | F9: IfcSpace | G9: Altro (B09) / Other (B10) | H9: pr_Illuminance | I9: not read | J9: lux | K9: – | L9: – | M9: – | N9: Lights | O9: Lighting_Level (= Design Level, W) hard-coded 300 | P9: W | Q9: none | R9: – | S9: No | T9: TopologicCellComplexToIDF (scripts/01_bim_to_bem.py) | U9: 150 / 200 / 300 / 500; Undefined (×12) | V9: 150 / 200 / 300 / 500; Undefined (×7) | W9: 300 written in Lighting_Level but ignored (method = Watts/Area) | X9: same | Y9: The 300 is not lux: in E+ 'Lighting Level' is a power in W and is unused when Design Level Calculation Method = Watts/Area.
A10: S09 | B10: T7 | C10: Lighting Power Density | D10: Cell | E10: pr_LightingPowerDensity | F10: IfcSpace | G10: Altro (B09) / Other (B10) | H10: pr_LightingPowerDensity | I10: Topologic JSON | J10: W/m² | K10: Area-weighted mean | L10: Room → Lighting (from office program, then overwritten in IDF) | M10: properties.energy.lighting.watts_per_area | N10: Lights | O10: Watts_per_Floor_Area (Design Level Calculation Method = Watts/Area) | P10: W/m² | Q10: 1:1 | R10: 0 | S10: Yes | T10: TopologicCellComplexToIDF (scripts/01_bim_to_bem.py) | U10: 6 / 7 | V10: 6 | W10: B09: 0 / 6 / 7 | B10: 6 | X10: B09: 0 / 6 / 7 | B10: 6 | Y10: Return-air 0, radiant 0.7, visible 0.2 (HB office defaults).
A11: S10 | B11: T7 | C11: Lighting Level | D11: – | E11: (not in TBIM) | F11: – | G11: – | H11: – | I11: – | J11: W | K11: – | L11: – | M11: – | N11: Lights | O11: Design_Level | P11: W | Q11: – | R11: – | S11: No | T11: – | U11: – | V11: – | W11: computed internally by E+ (W/m² × floor area) | X11: same | Y11: Paper says 'Calculate from Power Density · Area'; this is done by E+, not by the workflow.
A12: S11 | B12: T7 | C12: Equipment Power Density | D12: Cell | E12: pr_EquipmentPowerDensity | F12: IfcSpace | G12: Altro (B09) / Other (B10) | H12: pr_EquipmentPowerDensity | I12: Topologic JSON | J12: W/m² | K12: Area-weighted mean | L12: Room → ElectricEquipment (office program, overwritten in IDF) | M12: properties.energy.electric_equipment.watts_per_area | N12: ElectricEquipment | O12: Watts_per_Floor_Area (method Watts/Area) | P12: W/m² | Q12: 1:1 | R12: 0 ('Undefined' → 0 in TBIM.Cells_CleanUndefinedData) | S12: Partial | T12: TopologicCellComplexToIDF (scripts/01_bim_to_bem.py) | U12: Undefined | V12: 0; Undefined (×46) | W12: B09: 0 | B10: 0 | X12: B09: 0 / 2 | B10: 0 / 2 / 10 | Y12: Undefined in the TBIM for every space → 0 W/m² in the baseline; 2 and 10 W/m² were typed manually during calibration.
A13: S12 | B13: T7 | C13: Occupancy Density Operation | D13: Cell | E13: pr_OccupancyDensityOperation | F13: IfcSpace | G13: Altro (B09) / Other (B10) | H13: pr_OccupancyDensityOperation | I13: Topologic JSON | J13: pp/m² | K13: Area-weighted mean | L13: Room → People (office program, overwritten in IDF) | M13: properties.energy.people.people_per_area | N13: People | O13: People_per_Floor_Area (Number of People Calculation Method = People/Area) | P13: person/m² | Q13: 1:1 | R13: 0 | S13: Yes | T13: TopologicCellComplexToIDF (scripts/01_bim_to_bem.py) | U13: 0 / 0.12 / 0.3 / 0.6; Undefined (×12) | V13: 0 / 0.3 / 0.6 / 0.8; Undefined (×10) | W13: B09: 0 / 0.12 / 0.3 / 0.6 | B10: 0 / 0.3 / 0.6 / 0.8 | X13: B09: 0 / 0.12 / 0.3 / 0.6 | B10: 0 / 0.3 / 0.6 / 0.8 | Y13: Activity schedule 'Seated Adult Activity', radiant fraction 0.3 (HB office defaults). Also a K-Means feature.
A14: S13 | B14: T7 | C14: Occupancy Density Safety | D14: Cell | E14: pr_OccupancyDensitySafety | F14: IfcSpace | G14: Altro (B09) / Other (B10) | H14: pr_OccupancyDensitySafety | I14: Topologic JSON | J14: pp/m² | K14: Area-weighted mean (stored on zone) | L14: – | M14: – | N14: – | O14: – | P14: – | Q14: none | R14: 0 | S14: No | T14: Utils.TopologicZoneInheritSpaceData (Operation.py:4) | U14: 0 / 0.4 / 1.2 | V14: 0 / 0.01 / 0.4 / 0.7 / 1.2 | W14: – | X14: – | Y14: Fire-safety design density; not an energy input.
A15: S14 | B15: T7 | C15: Occupancy Number | D15: Cell | E15: pr_OccupancyNumber / pr_OccupancyNumberPeak | F15: IfcSpace | G15: Altro (B09) / Other (B10) | H15: pr_OccupancyNumberPeak | I15: not read | J15: pp | K15: – | L15: – | M15: – | N15: – | O15: – | P15: – | Q15: – | R15: – | S15: No | T15: – | U15: 16–158 (10 distinct); None (×122) | V15: 49 / 126 / 162 / 180; None (×45) | W15: – | X15: – | Y15: Present only on some cells. Occupant count in E+ = People/Area × floor area × schedule.
A16: S15 | B16: T7 | C16: Mechanical Ventilation Rate | D16: Cell | E16: pr_MechanicalVentilationRate | F16: IfcSpace | G16: Altro (B09) / Other (B10) | H16: pr_MechanicalVentilationRate | I16: Topologic JSON | J16: h⁻¹ per paper; used as L/s·m² by code | K16: Code intends volume-weighted mean, but zone value = value of LAST cell iterated (Operation.py:170 writes pr_MechanicalVentilationRate, not pr_ZoneMechanicalVentilationRate) | L16: Room → Ventilation (office program, overwritten in IDF) | M16: properties.energy.ventilation.flow_per_area | N16: DesignSpecification:OutdoorAir | O16: Outdoor_Air_Flow_per_Zone_Floor_Area (Outdoor Air Method = Maximum) | P16: m³/s·m² | Q16: ÷ 1000 | R16: 0 | S16: Yes | T16: TopologicCellComplexToIDF (scripts/01_bim_to_bem.py) | U16: 0–1332.16 (60 distinct) | V16: 0–8 (9 distinct); Undefined (×3) | W16: B09: 0–0.008 (38 distinct) | B10: 0–0.008 (9 distinct) | X16: B09: 0–0.008 (38 distinct) | B10: 0–0.008 (9 distinct) | Y16: Stored value is an air-change rate (h⁻¹) = N_peak × 7 L/s·p × 3.6 / V_net, but the code writes it as L/s·m² (see I07). Restrooms: 8 h⁻¹ → 0.008 m³/s·m².
A17: S16 | B17: T7 | C17: Mechanical Ventilation Rate Per Person | D17: Cell | E17: pr_MechanicalVentilationRatePerPerson | F17: IfcSpace | G17: Altro (B09) / Other (B10) | H17: (only in TBIM JSON) | I17: Topologic JSON | J17: L/s·person | K17: Occupant-weighted mean | L17: Room → Ventilation | M17: properties.energy.ventilation.flow_per_person | N17: DesignSpecification:OutdoorAir | O17: Outdoor_Air_Flow_per_Person | P17: m³/s·person | Q17: ÷ 1000 | R17: 0 | S17: Yes | T17: TopologicCellComplexToIDF (scripts/01_bim_to_bem.py) | U17: 0 / 7 | V17: 0 / 7 | W17: B09: 0 / 0.007 | B10: 0 / 0.007 | X17: B09: 0 / 0.007 | B10: 0 / 0.007 | Y17: Referenced by HVACTemplate:Zone:IdealLoadsAirSystem (Outdoor Air Method = DetailedSpecification). 'Maximum' = max(per-person, per-area), not their sum.
A18: S17 | B18: T7 | C18: Mechanical Ventilation Rate Per Volume | D18: Cell | E18: pr_MechanicalVentilationRatePerVolume | F18: IfcSpace | G18: Altro (B09) / Other (B10) | H18: pr_MechanicalVentilationRatePerVolume | I18: Topologic JSON | J18: h⁻¹ | K18: – | L18: – | M18: – | N18: – | O18: – | P18: – | Q18: none | R18: 0 | S18: No | T18: TBIM.Cells_CleanUndefinedData only | U18: 0 / 1 / 8 | V18: 0 / 1 / 8 | W18: – | X18: – | Y18: For stairs/elevators/restrooms the same number is also stored in pr_MechanicalVentilationRate, which is what reaches E+.
A19: S18 | B19: T7 | C19: Natural Ventilation Rate | D19: – | E19: (not in TBIM) | F19: – | G19: – | H19: – | I19: notebook constant | J19: – | K19: – | L19: – | M19: – | N19: ZoneInfiltration:DesignFlowRate | O19: see Map_Model M16 | P19: – | Q19: – | R19: – | S19: No | T19: – | U19: – | V19: – | W19: – | X19: – | Y19: Paper reports 0.30 h⁻¹ 'baseline envelope infiltration'; the model uses 0.0001 m³/s per m² of exterior surface (see M16 / I09).
A20: S19 | B20: T7 | C20: Space Temperature Summer Max | D20: Cell | E20: pr_SpaceTemperatureSummerMax | F20: IfcSpace | G20: Altro (B09) / Other (B10) | H20: pr_SpaceTemperatureSummerMax | I20: Topologic JSON | J20: °C | K20: Minimum over cells (stored on zone) | L20: Room → Setpoint | M20: cooling_schedule = ScheduleRuleset.from_constant_value('Generic room Cooling', 26) – NOT from TBIM | N20: HVACTemplate:Thermostat → Schedule | O20: Cooling_Setpoint_Schedule_Name = 'Generic room Cooling' | P20: °C | Q20: none | R20: 26 (B09 nb) / 30 (TBIM.Cells_CleanUndefinedData) | S20: No | T20: HB.HBRoomSetSetpointSchedules (Operation.py:541) | U20: 26; Undefined (×21) | V20: 26; Undefined (×14) | W20: Schedule:Constant 26 °C (both buildings) | X20: Schedule:Compact 20 °C (B09) / 22 °C (B10), all day | Y20: TBIM temperature limits are not transferred; see Issues I04.
A21: S20 | B21: T7 | C21: Space Temperature Summer Min | D21: Cell | E21: pr_SpaceTemperatureSummerMin | F21: IfcSpace | G21: Altro (B09) / Other (B10) | H21: pr_SpaceTemperatureSummerMin | I21: Topologic JSON | J21: °C | K21: Minimum over cells (stored on zone) | L21: – | M21: – | N21: – | O21: – | P21: – | Q21: none | R21: 23 (B09 nb) / 28 (CleanUndefinedData) | S21: No | T21: Utils.TopologicZoneInheritSpaceData (Operation.py:4) | U21: 23; Undefined (×21) | V21: 23; Undefined (×14) | W21: – | X21: –
A22: S21 | B22: T7 | C22: Space Temperature Winter Max | D22: Cell | E22: pr_SpaceTemperatureWinterMax | F22: IfcSpace | G22: Altro (B09) / Other (B10) | H22: pr_SpaceTemperatureWinterMax | I22: Topologic JSON | J22: °C | K22: Maximum over cells (stored on zone) | L22: – | M22: – | N22: – | O22: – | P22: – | Q22: none | R22: 23.5 (B09 nb) / 16 (CleanUndefinedData) | S22: No | T22: Utils.TopologicZoneInheritSpaceData (Operation.py:4) | U22: 23.5; Undefined (×21) | V22: 23.5; Undefined (×14) | W22: – | X22: –
A23: S22 | B23: T7 | C23: Space Temperature Winter Min | D23: Cell | E23: pr_SpaceTemperatureWinterMin | F23: IfcSpace | G23: Altro (B09) / Other (B10) | H23: pr_SpaceTemperatureWinterMin | I23: Topologic JSON | J23: °C | K23: Maximum over cells (stored on zone) | L23: Room → Setpoint | M23: heating_schedule = constant 'Generic room Heating' 20 °C – NOT from TBIM | N23: HVACTemplate:Thermostat → Schedule | O23: Heating_Setpoint_Schedule_Name = 'Generic room Heating' | P23: °C | Q23: none | R23: 18 (B09 nb) / 10 (CleanUndefinedData) | S23: No | T23: HB.HBRoomSetSetpointSchedules | U23: 18; Undefined (×21) | V23: 18; Undefined (×14) | W23: Schedule:Constant 20 °C | X23: B09: 15 °C (0–7 h) / 18 °C (7–18 h) / 15 °C; B10: 18 / 22 / 18 °C | Y23: See Issues I04.
A24: S23 | B24: T7 | C24: Space Humidity Max | D24: Cell | E24: pr_HumidityMax | F24: IfcSpace | G24: Altro (B09) / Other (B10) | H24: pr_HumidityMax | I24: Topologic JSON | J24: % RH | K24: Minimum over cells | L24: Room → IdealAirSystem (add_default_ideal_air) | M24: – (written after export) | N24: HVACTemplate:Zone:IdealLoadsAirSystem | O24: Dehumidification_Setpoint (Dehumidification Control Type = Humidistat) | P24: % RH | Q24: 1:1 | R24: 100 (TBIM.Cells_CleanUndefinedData) | S24: Yes | T24: TopologicCellComplexToIDF (scripts/01_bim_to_bem.py) | U24: 70; Undefined (×12) | V24: 70; Undefined (×11) | W24: B09: 70 / 100 | B10: 70 / 100 | X24: B09: 70 / 100 | B10: 70 / 100 | Y24: HB also writes unused constant schedules 'Generic room Dehumidifying' 60 % / 'Generic room Humidifying' 10 %.
A25: S24 | B25: T7 | C25: Space Humidity Min | D25: Cell | E25: pr_HumidityMin | F25: IfcSpace | G25: Altro (B09) / Other (B10) | H25: pr_HumidityMin | I25: Topologic JSON | J25: % RH | K25: Maximum over cells | L25: Room → IdealAirSystem | M25: – | N25: HVACTemplate:Zone:IdealLoadsAirSystem | O25: Humidification_Setpoint (Humidification Control Type = Humidistat) | P25: % RH | Q25: 1:1 | R25: 0 | S25: Yes | T25: TopologicCellComplexToIDF (scripts/01_bim_to_bem.py) | U25: 40; Undefined (×12) | V25: 40; Undefined (×11) | W25: B09: 0 / 40 | B10: 0 / 40 | X25: B09: 0 / 40 | B10: 0 / 40
A26: S25 | B26: T7 | C26: Space Wind Load Rating | D26: Cell | E26: pr_SpaceWindLoadRating | F26: IfcSpace | G26: Altro (B09) / Other (B10) | H26: pr_SpaceWindLoadRating | I26: not read | J26: class | K26: – | L26: – | M26: – | N26: – | O26: – | P26: – | Q26: – | R26: – | S26: No | T26: – | U26: Undefined (×67); A4 (×59); None (×29) | V26: Undefined (×33); None (×12); A4 (×4) | W26: – | X26: – | Y26: Paper says 'Eurocode 1 / Class 3'; the model stores window class 'A4' (EN 12210).
A27: S26 | B27: – (new) | C27: Occupancy schedule | D27: Cell (added by nb) | E27: rl_IsScheduledBy_Occupancy | F27: IfcSpace | G27: Altro (B09) / Other (B10) | H27: rl_IsScheduledBy_Occupancy | I27: IFC DesignTransferView | J27: schedule id | K27: Value of LAST cell iterated (Operation.py:174 uses rl_IsScheduledBy_*, not rl_ZoneIsScheduledBy_*) | L27: Room → People | M27: occupancy_schedule (overwritten in IDF) | N27: People | O27: Number_of_People_Schedule_Name | P27: – | Q27: id; prefix 'OccSch_' | R27: 'OccSch_Unoccupied' | S27: Yes | T27: scripts/01_bim_to_bem.py+ TopologicCellComplexToIDF (scripts/01_bim_to_bem.py) | U27: None (×71); OccSch_Unoccupied (×67); OccSch_B0.1 (×2); OccSch_B0.7 (×1); OccSch_B0.6 (×1); OccSch_B0.5 (×1); OccSch_B1.3 (×1); OccSch_B0.4 (×1); OccSch_B0.3 (×1); OccSch_B0.2 (×1); OccSch_B1.5 (×1); OccSch_B1.4 (×1); OccSch_B1.2 (×1); OccSch_B1.1 (×1); OccSch_B2.4 (×1); OccSch_B2.3 (×1); OccSch_B2.6 (×1); OccSch_B2.5 (×1); OccSch_B2.2 (×1) | V27: OccSch_Unoccupied (×31); None (×13); OccSch_A0.1/A0.2 (×2); OccSch_A1.3 (×1); OccSch_A1.2 (×1); OccSch_A1.1 (×1) | W27: B09: OccSch_Unoccupied (×47); OccSch_B0.1 (×2); OccSch_B0.7 (×1); OccSch_B0.6 (×1); OccSch_B0.5 (×1); OccSch_B1.3 (×1); OccSch_B0.4 (×1); OccSch_B0.3 (×1); OccSch_B0.2 (×1); OccSch_B1.5 (×1); OccSch_B1.4 (×1); OccSch_B1.2 (×1); OccSch_B1.1 (×1); OccSch_B2.3 (×1); OccSch_B2.4 (×1); OccSch_B2.6 (×1); OccSch_B2.5 (×1); OccSch_B2.2 (×1) | B10: OccSch_Unoccupied (×15); OccSch_A0.1/A0.2 (×2); OccSch_A1.3 (×1); OccSch_A1.2 (×1); OccSch_A1.1 (×1) | X27: B09: OccSch_Unoccupied (×47); OccSch_B0.1 (×2); OccSch_B0.7 (×1); OccSch_B0.6 (×1); OccSch_B0.5 (×1); OccSch_B1.3 (×1); OccSch_B0.4 (×1); OccSch_B0.3 (×1); OccSch_B0.2 (×1); OccSch_B1.5 (×1); OccSch_B1.4 (×1); OccSch_B1.2 (×1); OccSch_B1.1 (×1); OccSch_B2.3 (×1); OccSch_B2.4 (×1); OccSch_B2.6 (×1); OccSch_B2.5 (×1); OccSch_B2.2 (×1) | B10: OccSch_Unoccupied (×15); OccSch_A0.1/A0.2 (×2); OccSch_A1.3 (×1); OccSch_A1.2 (×1); OccSch_A1.1 (×1) | Y27: Schedules defined in _schedules/Schedules_Occupancy_PoliMi_LC.json (see Val_Schedules).
A28: S27 | B28: – (new) | C28: Lighting schedule | D28: Cell (added by nb) | E28: rl_IsScheduledBy_Lighting | F28: IfcSpace | G28: Altro (B09) / Other (B10) | H28: rl_IsScheduledBy_Lighting | I28: IFC DesignTransferView | J28: schedule id | K28: Value of last cell iterated | L28: Room → Lighting | M28: schedule (overwritten in IDF) | N28: Lights | O28: Schedule_Name | P28: – | Q28: first token before ';' | R28: 'AlwaysOff' (cell); 'LghSch_Costant' (B09 zone fix) | S28: Yes | T28: scripts/01_bim_to_bem.py+ TopologicCellComplexToIDF (scripts/01_bim_to_bem.py) | U28: None (×71); LghSch_Costant (×53); LghSch_Unoccupied (×14); LghSch_Costant;LghSch_B0.1 (×2); LghSch_Costant;LghSch_B0.7 (×1); LghSch_Costant;LghSch_B0.6 (×1); LghSch_Costant;LghSch_B0.5 (×1); LghSch_Costant;LghSch_B1.3 (×1); LghSch_Costant;LghSch_B0.4 (×1); LghSch_Costant;LghSch_B0.3 (×1); LghSch_Costant;LghSch_B0.2 (×1); LghSch_Costant;LghSch_B1.5 (×1); LghSch_Costant;LghSch_B1.4 (×1); LghSch_Costant;LghSch_B1.2 (×1); LghSch_Costant;LghSch_B1.1 (×1); LghSch_Costant;LghSch_B2.4 (×1); LghSch_Costant;LghSch_B2.3 (×1); LghSch_Costant;LghSch_B2.6 (×1); LghSch_Costant;LghSch_B2.5 (×1); LghSch_Costant;LghSch_B2.2 (×1) | V28: LghSch_Unoccupied (×16); LghSch_Costant (×15); None (×14); LghSch_A1.3;LghSch_Costant (×1); LghSch_A1.2;LghSch_Costant (×1); LghSch_A1.1;LghSch_Costant (×1); LghSch_A0.1/A0.2;LghSch_Costant (×1) | W28: B09: LghSch_Costant (×55); AlwaysOff (×9); LghSch_Unoccupied (×1) | B10: LghSch_Costant (×7); AlwaysOff (×5); LghSch_Unoccupied (×4); LghSch_A1.3 (×1); LghSch_A1.2 (×1); LghSch_A1.1 (×1); LghSch_A0.1/A0.2 (×1) | X28: B09: LghSch_Costant (×55); AlwaysOff (×9); LghSch_Unoccupied (×1) | B10: LghSch_Costant (×7); AlwaysOff (×5); LghSch_Unoccupied (×4); LghSch_A1.3 (×1); LghSch_A1.2 (×1); LghSch_A1.1 (×1); LghSch_A0.1/A0.2 (×1) | Y28: Multi-valued IFC entries such as 'LghSch_Costant;LghSch_B0.1' keep only the FIRST id. 'LghSch_Costant' = 0 all year in the baseline (see I06).
A29: S28 | B29: – (new) | C29: Equipment schedule | D29: Cell (added by nb) | E29: rl_IsScheduledBy_Equipment | F29: IfcSpace | G29: Altro (B09) / Other (B10) | H29: rl_IsScheduledBy_Equipment | I29: IFC DesignTransferView | J29: schedule id | K29: Value of last cell iterated | L29: Room → ElectricEquipment | M29: schedule (overwritten in IDF) | N29: ElectricEquipment | O29: Schedule_Name | P29: – | Q29: first token before ';' | R29: 'AlwaysOff' (cell); 'EqpSch_Unoccupied' (B09 zone fix) | S29: Yes | T29: scripts/01_bim_to_bem.py+ TopologicCellComplexToIDF (scripts/01_bim_to_bem.py) | U29: None (×71); EqpSch_Costant (×53); EqpSch_Unoccupied (×14); EqpSch_Costant;EqpSch_B0.1 (×2); EqpSch_Costant;EqpSch_B0.7 (×1); EqpSch_Costant;EqpSch_B0.6 (×1); EqpSch_Costant;EqpSch_B0.5 (×1); EqpSch_Costant;EqpSch_B1.3 (×1); EqpSch_Costant;EqpSch_B0.4 (×1); EqpSch_Costant;EqpSch_B0.3 (×1); EqpSch_Costant;EqpSch_B0.2 (×1); EqpSch_Costant;EqpSch_B1.5 (×1); EqpSch_Costant;EqpSch_B1.4 (×1); EqpSch_Costant;EqpSch_B1.2 (×1); EqpSch_Costant;EqpSch_B1.1 (×1); EqpSch_Costant;EqpSch_B2.4 (×1); EqpSch_Costant;EqpSch_B2.3 (×1); EqpSch_Costant;EqpSch_B2.6 (×1); EqpSch_Costant;EqpSch_B2.5 (×1); EqpSch_Costant;EqpSch_B2.2 (×1) | V29: EqpSch_Costant (×18); None (×14); EqpSch_Unoccupied (×13); EqpSch_A1.3;EqpSch_Costant (×1); EqpSch_A1.2;EqpSch_Costant (×1); EqpSch_A1.1;EqpSch_Costant (×1); EqpSch_A0.1/A0.2;EqpSch_Costant (×1) | W29: B09: EqpSch_Costant (×55); AlwaysOff (×9); EqpSch_Unoccupied (×1) | B10: EqpSch_Costant (×6); EqpSch_Unoccupied (×5); AlwaysOff (×5); EqpSch_A1.3 (×1); EqpSch_A1.2 (×1); EqpSch_A1.1 (×1); EqpSch_A0.1/A0.2 (×1) | X29: B09: EqpSch_Costant (×55); AlwaysOff (×9); EqpSch_Unoccupied (×1) | B10: EqpSch_Costant (×6); EqpSch_Unoccupied (×5); AlwaysOff (×5); EqpSch_A1.3 (×1); EqpSch_A1.2 (×1); EqpSch_A1.1 (×1); EqpSch_A0.1/A0.2 (×1) | Y29: 'EqpSch_Costant' (sic) is a copy of EqpSch_Unoccupied created in the notebook.
